<?xml version="1.0" encoding="utf-8"?>
<!-- This URDF was automatically created by SolidWorks to URDF Exporter! Originally created by Stephen Brawner (brawner@gmail.com) 
     Commit Version: 1.5.1-0-g916b5db  Build Version: 1.5.7152.31018
     For more information, please see http://wiki.ros.org/sw_urdf_exporter -->
<robot
  name="lingao_description">
  <link
    name="base_link">
    <visual>
      <origin
        xyz="0 0 0"
        rpy="0 0 0" />
      <geometry>
        <mesh
          filename="package://lingao_description/meshes/LA_4WD_LingFeng/LingFeng_base.STL" />
      </geometry>
      <material
        name="">
        <color
          rgba="1 0.812 0 1" />
      </material>
    </visual>
    <collision>
      <origin
        xyz="0 0 0"
        rpy="0 0 0" />
      <geometry>
        <mesh
          filename="package://lingao_description/meshes/LA_4WD_LingFeng/LingFeng_base.STL" />
      </geometry>
    </collision>
  </link>
  <link
    name="wheel_la_link">
    <visual>
      <origin
        xyz="0 0 0"
        rpy="0 0 0" />
      <geometry>
        <mesh
          filename="package://lingao_description/meshes/LA_4WD_LingFeng/wheel_left.STL" />
      </geometry>
      <material
        name="">
        <color
          rgba="0.2 0.2 0.2 1" />
      </material>
    </visual>
    <collision>
      <origin
        xyz="0 0 0"
        rpy="0 0 0" />
      <geometry>
        <mesh
          filename="package://lingao_description/meshes/LA_4WD_LingFeng/wheel_left.STL" />
      </geometry>
    </collision>
  </link>
  <joint
    name="wheel_la_joint"
    type="continuous">
    <origin
      xyz="0.12 0.1595 0.02"
      rpy="0 0 0" />
    <parent
      link="base_link" />
    <child
      link="wheel_la_link" />
    <axis
      xyz="0 1 0" />
  </joint>
  <link
    name="wheel_lb_link">
    <visual>
      <origin
        xyz="0 0 0"
        rpy="0 0 0" />
      <geometry>
        <mesh
          filename="package://lingao_description/meshes/LA_4WD_LingFeng/wheel_left.STL" />
      </geometry>
      <material
        name="">
        <color
          rgba="0.2 0.2 0.2 1" />
      </material>
    </visual>
    <collision>
      <origin
        xyz="0 0 0"
        rpy="0 0 0" />
      <geometry>
        <mesh
          filename="package://lingao_description/meshes/LA_4WD_LingFeng/wheel_left.STL" />
      </geometry>
    </collision>
  </link>
  <joint
    name="wheel_lb_joint"
    type="continuous">
    <origin
      xyz="-0.12 0.1595 0.02"
      rpy="0 0 0" />
    <parent
      link="base_link" />
    <child
      link="wheel_lb_link" />
    <axis
      xyz="0 1 0" />
  </joint>
  <link
    name="wheel_ra_link">
    <visual>
      <origin
        xyz="0 0 0"
        rpy="0 0 0" />
      <geometry>
        <mesh
          filename="package://lingao_description/meshes/LA_4WD_LingFeng/wheel_right.STL" />
      </geometry>
      <material
        name="">
        <color
          rgba="0.2 0.2 0.2 1" />
      </material>
    </visual>
    <collision>
      <origin
        xyz="0 0 0"
        rpy="0 0 0" />
      <geometry>
        <mesh
          filename="package://lingao_description/meshes/LA_4WD_LingFeng/wheel_right.STL" />
      </geometry>
    </collision>
  </link>
  <joint
    name="wheel_ra_joint"
    type="continuous">
    <origin
      xyz="0.12 -0.1595 0.02"
      rpy="0 0 0" />
    <parent
      link="base_link" />
    <child
      link="wheel_ra_link" />
    <axis
      xyz="0 1 0" />
  </joint>
  <link
    name="wheel_rb_link">
    <visual>
      <origin
        xyz="0 0 0"
        rpy="0 0 0" />
      <geometry>
        <mesh
          filename="package://lingao_description/meshes/LA_4WD_LingFeng/wheel_right.STL" />
      </geometry>
      <material
        name="">
        <color
          rgba="0.2 0.2 0.2 1" />
      </material>
    </visual>
    <collision>
      <origin
        xyz="0 0 0"
        rpy="0 0 0" />
      <geometry>
        <mesh
          filename="package://lingao_description/meshes/LA_4WD_LingFeng/wheel_right.STL" />
      </geometry>
    </collision>
  </link>
  <joint
    name="wheel_rb_joint"
    type="continuous">
    <origin
      xyz="-0.12 -0.1595 0.02"
      rpy="0 0 0" />
    <parent
      link="base_link" />
    <child
      link="wheel_rb_link" />
    <axis
      xyz="0 1 0" />
  </joint>
</robot>